Workbook

Sheet L
A1: 1 | B1: Beraca | C1: 0.65 | D1: T | E1: 90000 | F1: 300000
A2: 2 | B2: Vea | C2: 0.75 | D2: V | E2: 25000 | F2: 100000
A3: 3 | B3: ChangoMas | C3: 0.75 | D3: Lu | E3: 20000 | F3: 75000
A4: 4 | B4: Carrefour | C4: 1 | D4: Ju | E4: 12000 | F4: 40000
A5: 5 | B5: MB Carniceria | C5: 0.65
A6: 6 | B6: Fiambrisima | C6: 0.65
A7: 7 | B7: LaTradición | C7: 0.65
A8: 8 | B8: Cordero | C8: 1
A9: 9 | B9: LaPanaderia
A10: 10 | B10: SanCayetano
A11: 11 | B11: Shell YPF | C11: 0.75 | D11: V | E11: 10000 | F11: 50000
A12: 12 | B12: Farmacia | C12: 3c | D12: L
A13: 13 | B13: Farmar | C13: 20 | D13: MiV | E13: stope
A14: 14
A15: 15
A16: 16
A17: 17
A18: 18
A19: 19
A20: 20
A21: 21
A22: 22
A23: 23
A24: 24
A25: 25

Sheet B
A1: 1 | B1: =LOOKUP(A1,L!A:A,L!B:B) -> Beraca | H1: =IF(A1=1,SUMIFS(K3:K587,B3:B587,1),IF(A1=2,SUMIFS(K3:K587,B3:B587,2),IF(A1=3,SUMIFS(K3:K587,B3:B587,3),IF(A1=4,SUMIFS(K3:K587,B3:B587,4),IF(A1=5,SUMIFS(K3:K587,B3:B587,5),IF(A1=6,SUMIFS(K3:K587,B3:B587,6),IF(A1=7,SUMIFS(K3:K587,B3:B587,7),IF(A1=8,SUMIFS(K3:K587,B3:B587,8),IF(A1=9,SUMIFS(K3:K587,B3:B587,9),IF(A1=10,SUMIFS(K3:K587,B3:B587,10),IF(A1=11,SUMIFS(K3:K587,B3:B587,11),IF(A1=12,SUMIFS(K3:K587,B3:B587,12),"")))))))))))) -> 0
A3: SAB | B3: 1 | C3: AceiteGirsol | F3: 1500 | G3: 1000 | I3: 6899.25 | K3: =ROUND(H3*I3,2) -> 0 | L3: =IF(I3=0,"",I3/F3*G3*LOOKUP(B3,L!A:A,L!C:C)) -> 2989.675 | M3: =IF(L3=MIN(L3:L5),1,0) -> 0
A4: SAB | B4: 2 | C4: AceiteGirsol | E4: Cocinero | F4: 1500 | G4: 1000 | I4: 5650 | K4: =ROUND(H4*I4,2) -> 0 | L4: =IF(I4=0,"",I4/F4*G4*LOOKUP(B4,L!A:A,L!C:C)) -> 2825 | M4: =IF(L4=MIN(L3:L5),1,0) -> 1
A5: SAB | B5: 4 | C5: AceiteGirsol | E5: Cocinero | F5: 1000 | G5: 1000 | I5: 3000 | K5: =ROUND(H5*I5,2) -> 0 | L5: =IF(I5=0,"",I5/F5*G5*LOOKUP(B5,L!A:A,L!C:C)) -> 3000 | M5: =IF(L5=MIN(L3:L5),1,0) -> 0
A6: SAB | B6: 1 | C6: AceiteOliva | F6: 500 | G6: 1000 | I6: 10326.35 | K6: =ROUND(H6*I6,2) -> 0 | L6: =IF(I6=0,"",I6/F6*G6*LOOKUP(B6,L!A:A,L!C:C)) -> 13424.255 | M6: =IF(L6=MIN(L6:L8),1,0) -> 0
A7: SAB | B7: 2 | C7: AceiteOliva | F7: 500 | G7: 1000 | I7: 15660 | K7: =ROUND(H7*I7,2) -> 0 | L7: =IF(I7=0,"",I7/F7*G7*LOOKUP(B7,L!A:A,L!C:C)) -> 23490 | M7: =IF(L7=MIN(L6:L8),1,0) -> 0
A8: SAB | B8: 4 | C8: AceiteOliva | F8: 500 | G8: 1000 | I8: 3456 | K8: =ROUND(H8*I8,2) -> 0 | L8: =IF(I8=0,"",I8/F8*G8*LOOKUP(B8,L!A:A,L!C:C)) -> 6912 | M8: =IF(L8=MIN(L6:L8),1,0) -> 1
A9: SAB | B9: 1 | C9: Aceituna | F9: 200 | G9: 1000 | K9: =ROUND(H9*I9,2) -> 0 | L9: =IF(I9=0,"",I9/F9*G9*LOOKUP(B9,L!A:A,L!C:C)) | M9: =IF(L9=MIN(L9:L11),1,0) -> 0
A10: SAB | B10: 5 | C10: Aceituna | F10: 300 | G10: 1000 | I10: 222 | K10: =ROUND(H10*I10,2) -> 0 | L10: =IF(I10=0,"",I10/F10*G10*LOOKUP(B10,L!A:A,L!C:C)) -> 481 | M10: =IF(L10=MIN(L9:L11),1,0) -> 1
A11: SAB | B11: 4 | C11: Aceituna | G11: 1000 | K11: =ROUND(H11*I11,2) -> 0 | L11: =IF(I11=0,"",I11/F11*G11*LOOKUP(B11,L!A:A,L!C:C)) | M11: =IF(L11=MIN(L9:L11),1,0) -> 0
A12: VEC | B12: 1 | C12: Acelga | F12: 1 | G12: 1 | I12: 564 | K12: =ROUND(H12*I12,2) -> 0 | L12: =IF(I12=0,"",I12/F12*G12*LOOKUP(B12,L!A:A,L!C:C)) -> 366.6 | M12: =IF(L12=MIN(L12:L14),1,0) -> 1
A13: VEC | B13: 2 | C13: Acelga | F13: 1 | G13: 1 | K13: =ROUND(H13*I13,2) -> 0 | L13: =IF(I13=0,"",I13/F13*G13*LOOKUP(B13,L!A:A,L!C:C)) | M13: =IF(L13=MIN(L12:L14),1,0) -> 0
A14: VEC | B14: 4 | C14: Acelga | F14: 1 | G14: 1 | K14: =ROUND(H14*I14,2) -> 0 | L14: =IF(I14=0,"",I14/F14*G14*LOOKUP(B14,L!A:A,L!C:C)) | M14: =IF(L14=MIN(L12:L14),1,0) -> 0
A15: LIM | B15: 1 | C15: Desinfectante | E15: Lysoform | F15: 360 | G15: 1000 | I15: 4529.35 | K15: =ROUND(H15*I15,2) -> 0 | L15: =IF(I15=0,"",I15/F15*G15*LOOKUP(B15,L!A:A,L!C:C)) -> 8177.9931 | M15: =IF(L15=MIN(L15:L17),1,0) -> 1
A16: LIM | B16: 2 | C16: Desinfectante | F16: 360 | G16: 1000 | K16: =ROUND(H16*I16,2) -> 0 | L16: =IF(I16=0,"",I16/F16*G16*LOOKUP(B16,L!A:A,L!C:C)) | M16: =IF(L16=MIN(L15:L17),1,0) -> 0
A17: LIM | B17: 4 | C17: Desinfectante | F17: 360 | G17: 1000 | K17: =ROUND(H17*I17,2) -> 0 | L17: =IF(I17=0,"",I17/F17*G17*LOOKUP(B17,L!A:A,L!C:C)) | M17: =IF(L17=MIN(L15:L17),1,0) -> 0
A18: BBD | B18: 1 | C18: AguaMineral | E18: Benedictino | F18: 6250 | G18: 1000 | H18: 0 | I18: 4205.49 | K18: =ROUND(H18*I18,2) -> 0 | L18: =IF(I18=0,"",I18/F18*G18*LOOKUP(B18,L!A:A,L!C:C)) -> 437.37096 | M18: =IF(L18=MIN(L18:L20),1,0) -> 1
A19: BBD | B19: 4 | C19: AguaMineral | E19: Benedictino | F19: 6250 | G19: 1000 | K19: =ROUND(H19*I19,2) -> 0 | L19: =IF(I19=0,"",I19/F19*G19*LOOKUP(B19,L!A:A,L!C:C)) | M19: =IF(L19=MIN(L18:L20),1,0) -> 0
A20: BBD | B20: 3 | C20: AguaMineral | E20: Benedictino | F20: 6250 | G20: 1000 | I20: 5199 | K20: =ROUND(H20*I20,2) -> 0 | L20: =IF(I20=0,"",I20/F20*G20*LOOKUP(B20,L!A:A,L!C:C)) -> 623.88 | M20: =IF(L20=MIN(L18:L20),1,0) -> 0
A21: VEC | B21: 1 | C21: AjoCabeza | F21: 1 | G21: 1 | I21: 1654 | K21: =ROUND(H21*I21,2) -> 0 | L21: =IF(I21=0,"",I21/F21*G21*LOOKUP(B21,L!A:A,L!C:C)) -> 1075.1 | M21: =IF(L21=MIN(L21:L23),1,0) -> 1
A22: VEC | B22: 2 | C22: AjoCabeza | F22: 1 | G22: 1 | K22: =ROUND(H22*I22,2) -> 0 | L22: =IF(I22=0,"",I22/F22*G22*LOOKUP(B22,L!A:A,L!C:C)) | M22: =IF(L22=MIN(L21:L23),1,0) -> 0
A23: VEC | B23: 4 | C23: AjoCabeza | F23: 1 | G23: 1 | I23: 5600 | K23: =ROUND(H23*I23,2) -> 0 | L23: =IF(I23=0,"",I23/F23*G23*LOOKUP(B23,L!A:A,L!C:C)) -> 5600 | M23: =IF(L23=MIN(L21:L23),1,0) -> 0
A24: VER | B24: 1 | C24: Albahaca | F24: 1 | G24: 1 | K24: =ROUND(H24*I24,2) -> 0 | L24: =IF(I24=0,"",I24/F24*G24*LOOKUP(B24,L!A:A,L!C:C)) | M24: =IF(L24=MIN(L24:L26),1,0) -> 0
A25: VER | B25: 2 | C25: Albahaca | G25: 1 | K25: =ROUND(H25*I25,2) -> 0 | L25: =IF(I25=0,"",I25/F25*G25*LOOKUP(B25,L!A:A,L!C:C)) | M25: =IF(L25=MIN(L24:L26),1,0) -> 0
A26: VER | B26: 4 | C26: Albahaca | G26: 1 | K26: =ROUND(H26*I26,2) -> 0 | L26: =IF(I26=0,"",I26/F26*G26*LOOKUP(B26,L!A:A,L!C:C)) | M26: =IF(L26=MIN(L24:L26),1,0) -> 0
A27: HIG | B27: 1 | C27: Alcohol | F27: 1000 | G27: 1000 | K27: =ROUND(H27*I27,2) -> 0 | L27: =IF(I27=0,"",I27/F27*G27*LOOKUP(B27,L!A:A,L!C:C)) | M27: =IF(L27=MIN(L27:L29),1,0) -> 0
A28: HIG | B28: 2 | C28: Alcohol | F28: 1000 | G28: 1000 | I28: 4750 | K28: =ROUND(H28*I28,2) -> 0 | L28: =IF(I28=0,"",I28/F28*G28*LOOKUP(B28,L!A:A,L!C:C)) -> 3562.5 | M28: =IF(L28=MIN(L27:L29),1,0) -> 1
A29: HIG | B29: 3 | C29: Alcohol | F29: 1000 | G29: 1000 | I29: 6349 | K29: =ROUND(H29*I29,2) -> 0 | L29: =IF(I29=0,"",I29/F29*G29*LOOKUP(B29,L!A:A,L!C:C)) -> 4761.75 | M29: =IF(L29=MIN(L27:L29),1,0) -> 0
A30: GLS | B30: 1 | C30: Alfajor | F30: 50 | G30: 1000 | I30: 1828.59 | K30: =ROUND(H30*I30,2) -> 0 | L30: =IF(I30=0,"",I30/F30*G30*LOOKUP(B30,L!A:A,L!C:C)) -> 23771.67 | M30: =IF(L30=MIN(L30:L32),1,0) -> 0
A31: GLS | B31: 3 | C31: Alfajor | F31: 228 | G31: 1000 | I31: 6769 | K31: =ROUND(H31*I31,2) -> 0 | L31: =IF(I31=0,"",I31/F31*G31*LOOKUP(B31,L!A:A,L!C:C)) -> 22266.447 | M31: =IF(L31=MIN(L30:L32),1,0) -> 0
A32: GLS | B32: 4 | C32: Alfajor | F32: 300 | G32: 1000 | H32: 0 | I32: 5200 | K32: =ROUND(H32*I32,2) -> 0 | L32: =IF(I32=0,"",I32/F32*G32*LOOKUP(B32,L!A:A,L!C:C)) -> 17333.333 | M32: =IF(L32=MIN(L30:L32),1,0) -> 1
A33: HIG | B33: 1 | C33: Algodon | F33: 100 | G33: 1000 | K33: =ROUND(H33*I33,2) -> 0 | L33: =IF(I33=0,"",I33/F33*G33*LOOKUP(B33,L!A:A,L!C:C)) | M33: =IF(L33=MIN(L33:L35),1,0) -> 0
A34: HIG | B34: 2 | C34: Algodon | F34: 140 | G34: 1000 | I34: 2400 | K34: =ROUND(H34*I34,2) -> 0 | L34: =IF(I34=0,"",I34/F34*G34*LOOKUP(B34,L!A:A,L!C:C)) -> 12857.143 | M34: =IF(L34=MIN(L33:L35),1,0) -> 1
A35: HIG | B35: 4 | C35: Algodon | F35: 140 | G35: 1000 | K35: =ROUND(H35*I35,2) -> 0 | L35: =IF(I35=0,"",I35/F35*G35*LOOKUP(B35,L!A:A,L!C:C)) | M35: =IF(L35=MIN(L33:L35),1,0) -> 0
A36: MSC | B36: 6 | C36: AlimentoDog | F36: 15000 | G36: 1000 | K36: =ROUND(H36*I36,2) -> 0 | L36: =IF(I36=0,"",I36/F36*G36*LOOKUP(B36,L!A:A,L!C:C)) | M36: =IF(L36=MIN(L36:L38),1,0) -> 0
A37: MSC | B37: 2 | C37: AlimentoDog | F37: 3000 | G37: 1000 | I37: 13000 | K37: =ROUND(H37*I37,2) -> 0 | L37: =IF(I37=0,"",I37/F37*G37*LOOKUP(B37,L!A:A,L!C:C)) -> 3250 | M37: =IF(L37=MIN(L36:L38),1,0) -> 1
A38: MSC | B38: 4 | C38: AlimentoDog | E38: HP | F38: 3000 | G38: 1000 | I38: 13450 | K38: =ROUND(H38*I38,2) -> 0 | L38: =IF(I38=0,"",I38/F38*G38*LOOKUP(B38,L!A:A,L!C:C)) -> 4483.3333 | M38: =IF(L38=MIN(L36:L38),1,0) -> 0
A39: FRU | B39: 1 | C39: Anana | F39: 1000 | G39: 1000 | K39: =ROUND(H39*I39,2) -> 0 | L39: =IF(I39=0,"",I39/F39*G39*LOOKUP(B39,L!A:A,L!C:C)) | M39: =IF(L39=MIN(L39:L41),1,0) -> 0
A40: FRU | B40: 2 | C40: Anana | E40: Arandanos | F40: 1000 | G40: 1000 | K40: =ROUND(H40*I40,2) -> 0 | L40: =IF(I40=0,"",I40/F40*G40*LOOKUP(B40,L!A:A,L!C:C)) | M40: =IF(L40=MIN(L39:L41),1,0) -> 0
A41: FRU | B41: 4 | C41: Anana | F41: 1000 | G41: 1000 | K41: =ROUND(H41*I41,2) -> 0 | L41: =IF(I41=0,"",I41/F41*G41*LOOKUP(B41,L!A:A,L!C:C)) | M41: =IF(L41=MIN(L39:L41),1,0) -> 0
...

Sheet F
A1: 31 | C1: 6 | D1: 100 | G1: =D1*A2/100+D2*D1/100 -> 25
A2: 5 | C2: =ROUND(D1/C1,2) -> 16.67 | D2: 20 | E2: Cuo | F2: Des | G2: A Pagar | H2: Cuo | I2: Des | J2: A Pagar
A3: 1 | B3: =IF(A3>$C$1,0,(D1+D3-C3)) -> 110.88 | C3: =IF(A3>$C$1,0,$C$2)-G1 -> -8.33 | D3: =ROUND(D1*A1*30/36500,2) -> 2.55 | E3: 1 | F3: 0 | H3: 1 | I3: 25 | O3: 60.75
A4: 2 | B4: =IF(A4>$C$1,0,(B3+D4-C4)) -> 97.04 | C4: =IF(A4>$C$1,0,$C$2) -> 16.67 | D4: =IF(A4>$C$1,0,ROUND(B3*$A$1*30/36500,2)) -> 2.83 | E4: 3 | F4: 0 | H4: 3 | I4: 25 | O4: 72.6
A5: 3 | B5: =IF(A5>$C$1,0,(B4+D5-C5)) -> 82.84 | C5: =IF(A5>$C$1,0,$C$2) -> 16.67 | D5: =IF(A5>$C$1,0,ROUND(B4*$A$1*30/36500,2)) -> 2.47 | E5: 6 | F5: 0 | H5: 6 | I5: 25 | O5: 67.2
A6: 4 | B6: =IF(A6>$C$1,0,(B5+D6-C6)) -> 68.28 | C6: =IF(A6>$C$1,0,$C$2) -> 16.67 | D6: =IF(A6>$C$1,0,ROUND(B5*$A$1*30/36500,2)) -> 2.11 | E6: 9 | F6: 0 | H6: 9 | I6: 25 | O6: 87.12
A7: 5 | B7: =IF(A7>$C$1,0,(B6+D7-C7)) -> 53.35 | C7: =IF(A7>$C$1,0,$C$2) -> 16.67 | D7: =IF(A7>$C$1,0,ROUND(B6*$A$1*30/36500,2)) -> 1.74 | E7: 12 | F7: 0 | H7: 12 | I7: 25 | O7: 133.81
A8: 6 | B8: =IF(A8>$C$1,0,(B7+D8-C8)) -> 38.04 | C8: =IF(A8>$C$1,0,$C$2) -> 16.67 | D8: =IF(A8>$C$1,0,ROUND(B7*$A$1*30/36500,2)) -> 1.36 | E8: 18 | F8: 0 | H8: 18 | I8: 25
A9: 7 | B9: =IF(A9>$C$1,0,(B8+D9-C9)) -> 0 | C9: =IF(A9>$C$1,0,$C$2) -> 0 | D9: =IF(A9>$C$1,0,ROUND(B8*$A$1*30/36500,2)) -> 0 | E9: 1 | F9: 10 | H9: 1 | I9: 30 | J9: 62.45
A10: 8 | B10: =IF(A10>$C$1,0,(B9+D10-C10)) -> 0 | C10: =IF(A10>$C$1,0,$C$2) -> 0 | D10: =IF(A10>$C$1,0,ROUND(B9*$A$1*30/36500,2)) -> 0 | E10: 3 | F10: 10 | H10: 3 | I10: 30
A11: 9 | B11: =IF(A11>$C$1,0,(B10+D11-C11)) -> 0 | C11: =IF(A11>$C$1,0,$C$2) -> 0 | D11: =IF(A11>$C$1,0,ROUND(B10*$A$1*30/36500,2)) -> 0 | E11: 6 | F11: 10 | H11: 6 | I11: 30
A12: 10 | B12: =IF(A12>$C$1,0,(B11+D12-C12)) -> 0 | C12: =IF(A12>$C$1,0,$C$2) -> 0 | D12: =IF(A12>$C$1,0,ROUND(B11*$A$1*30/36500,2)) -> 0 | E12: 9 | F12: 10 | H12: 9 | I12: 30
A13: 11 | B13: =IF(A13>$C$1,0,(B12+D13-C13)) -> 0 | C13: =IF(A13>$C$1,0,$C$2) -> 0 | D13: =IF(A13>$C$1,0,ROUND(B12*$A$1*30/36500,2)) -> 0 | E13: 12 | F13: 10 | H13: 12 | I13: 30
A14: 12 | B14: =IF(A14>$C$1,0,(B13+D14-C14)) -> 0 | C14: =IF(A14>$C$1,0,$C$2) -> 0 | D14: =IF(A14>$C$1,0,ROUND(B13*$A$1*30/36500,2)) -> 0 | E14: 18 | F14: 10 | H14: 18 | I14: 30
A15: 13 | B15: =IF(A15>$C$1,0,(B14+D15-C15)) -> 0 | C15: =IF(A15>$C$1,0,$C$2) -> 0 | D15: =IF(A15>$C$1,0,ROUND(B14*$A$1*30/36500,2)) -> 0 | E15: 1 | F15: 20 | H15: 1 | I15: 50
A16: 14 | B16: =IF(A16>$C$1,0,(B15+D16-C16)) -> 0 | C16: =IF(A16>$C$1,0,$C$2) -> 0 | D16: =IF(A16>$C$1,0,ROUND(B15*$A$1*30/36500,2)) -> 0 | E16: 3 | F16: 20 | H16: 3 | I16: 50
A17: 15 | B17: =IF(A17>$C$1,0,(B16+D17-C17)) -> 0 | C17: =IF(A17>$C$1,0,$C$2) -> 0 | D17: =IF(A17>$C$1,0,ROUND(B16*$A$1*30/36500,2)) -> 0 | E17: 6 | F17: 20 | G17: 61.96 | H17: 6 | I17: 50
A18: 16 | B18: =IF(A18>$C$1,0,(B17+D18-C18)) -> 0 | C18: =IF(A18>$C$1,0,$C$2) -> 0 | D18: =IF(A18>$C$1,0,ROUND(B17*$A$1*30/36500,2)) -> 0 | E18: 9 | F18: 20 | H18: 9 | I18: 50
A19: 17 | B19: =IF(A19>$C$1,0,(B18+D19-C19)) -> 0 | C19: =IF(A19>$C$1,0,$C$2) -> 0 | D19: =IF(A19>$C$1,0,ROUND(B18*$A$1*30/36500,2)) -> 0 | E19: 12 | F19: 20 | H19: 12 | I19: 50
A20: 18 | B20: =IF(A20>$C$1,0,(B19+D20-C20)) -> 0 | C20: =IF(A20>$C$1,0,$C$2) -> 0 | D20: =IF(A20>$C$1,0,ROUND(B19*$A$1*30/36500,2)) -> 0 | E20: 18 | F20: 20 | H20: 18 | I20: 50
A21: 19
A22: 20
A23: 21
A24: 22
A25: 23
A26: 24

Sheet Hoja 3
A1: Levadura | B1: galletas vainilla
A2: queso | B2: manteca 100
A3: crema leche | B3: queso crema 580
A4: salame | B4: es vainilla
A5: jamon | B5: limon
B6: crema doble
B7: azúcar
A8: cebolla | B8: fecula
A9: tomate | B9: huevos
B10: mermelada arandanos
